<?xml version="1.0" encoding="utf-8"?>
<!-- This URDF was automatically created by SolidWorks to URDF Exporter! Originally created by Stephen Brawner (brawner@gmail.com) 
     Commit Version: 1.6.0-1-g15f4949  Build Version: 1.6.7594.29634
     For more information, please see http://wiki.ros.org/sw_urdf_exporter -->
<robot
  name="robot_urdf_v9">
  <link
    name="base_link">
    <inertial>
      <origin
        xyz="-0.010725287622038 -5.55111512312578E-17 0.0196110486694259"
        rpy="0 0 0" />
      <mass
        value="0.507968943099814" />
      <inertia
        ixx="0.000615478419229214"
        ixy="1.81865140104002E-19"
        ixz="-0.00010139509653096"
        iyy="0.00129176722491481"
        iyz="9.58285334741693E-20"
        izz="0.00170980703054353" />
    </inertial>
    <visual>
      <origin
        xyz="0 0 0"
        rpy="0 0 0" />
      <geometry>
        <mesh
          filename="package://robot_urdf_v9/meshes/base_link.STL" />
      </geometry>
      <material
        name="">
        <color
          rgba="0.501960784313725 0.501960784313725 0.501960784313725 1" />
      </material>
    </visual>
    <collision>
      <origin
        xyz="0 0 0"
        rpy="0 0 0" />
      <geometry>
        <mesh
          filename="package://robot_urdf_v9/meshes/base_link.STL" />
      </geometry>
    </collision>
  </link>
  <link
    name="link_01">
    <inertial>
      <origin
        xyz="-0.0035531 0 0.014248"
        rpy="0 0 0" />
      <mass
        value="0.11708" />
      <inertia
        ixx="5.3193E-05"
        ixy="-2.1176E-22"
        ixz="4.2648E-06"
        iyy="5.0147E-05"
        iyz="-5.9939E-21"
        izz="7.6524E-05" />
    </inertial>
    <visual>
      <origin
        xyz="0 0 0"
        rpy="0 0 0" />
      <geometry>
        <mesh
          filename="package://robot_urdf_v9/meshes/link_01.STL" />
      </geometry>
      <material
        name="">
        <color
          rgba="0.2 0.4 0.69804 1" />
      </material>
    </visual>
    <collision>
      <origin
        xyz="0 0 0"
        rpy="0 0 0" />
      <geometry>
        <mesh
          filename="package://robot_urdf_v9/meshes/link_01.STL" />
      </geometry>
    </collision>
  </link>
  <joint
    name="joint_01"
    type="revolute">
    <origin
      xyz="0 0 0.037"
      rpy="0 0 0.072771" />
    <parent
      link="base_link" />
    <child
      link="link_01" />
    <axis
      xyz="0 0 1" />
    <limit
      lower="-2"
      upper="2"
      effort="1.4"
      velocity="4.5" />
  </joint>
  <link
    name="link_02">
    <inertial>
      <origin
        xyz="1.3878E-17 -5.5511E-17 0.048627"
        rpy="0 0 0" />
      <mass
        value="0.026007" />
      <inertia
        ixx="2.6165E-05"
        ixy="-4.1293E-21"
        ixz="-5.4428E-21"
        iyy="2.0139E-05"
        iyz="-6.4824E-20"
        izz="8.7189E-06" />
    </inertial>
    <visual>
      <origin
        xyz="0 0 0"
        rpy="0 0 0" />
      <geometry>
        <mesh
          filename="package://robot_urdf_v9/meshes/link_02.STL" />
      </geometry>
      <material
        name="">
        <color
          rgba="0.2 0.4 0.69804 1" />
      </material>
    </visual>
    <collision>
      <origin
        xyz="0 0 0"
        rpy="0 0 0" />
      <geometry>
        <mesh
          filename="package://robot_urdf_v9/meshes/link_02.STL" />
      </geometry>
    </collision>
  </link>
  <joint
    name="joint_02"
    type="revolute">
    <origin
      xyz="0 0 0.03"
      rpy="0 0.57607 0" />
    <parent
      link="link_01" />
    <child
      link="link_02" />
    <axis
      xyz="0 -1 0" />
    <limit
      lower="-1.2"
      upper="1.57"
      effort="1.9"
      velocity="4.7" />
  </joint>
  <link
    name="link_03">
    <inertial>
      <origin
        xyz="5.5511E-17 0 0.0475"
        rpy="0 0 0" />
      <mass
        value="0.075999" />
      <inertia
        ixx="9.4655E-05"
        ixy="-5.294E-22"
        ixz="2.259E-21"
        iyy="8.893E-05"
        iyz="-4.844E-20"
        izz="1.1131E-05" />
    </inertial>
    <visual>
      <origin
        xyz="0 0 0"
        rpy="0 0 0" />
      <geometry>
        <mesh
          filename="package://robot_urdf_v9/meshes/link_03.STL" />
      </geometry>
      <material
        name="">
        <color
          rgba="0.50196 0.50196 0.50196 1" />
      </material>
    </visual>
    <collision>
      <origin
        xyz="0 0 0"
        rpy="0 0 0" />
      <geometry>
        <mesh
          filename="package://robot_urdf_v9/meshes/link_03.STL" />
      </geometry>
    </collision>
  </link>
  <joint
    name="joint_03"
    type="revolute">
    <origin
      xyz="0 0 0.101"
      rpy="0 0.75371 0" />
    <parent
      link="link_02" />
    <child
      link="link_03" />
    <axis
      xyz="0 1 0" />
    <limit
      lower="-2"
      upper="2"
      effort="1.4"
      velocity="4.5" />
  </joint>
  <link
    name="link_04">
    <inertial>
      <origin
        xyz="0.011163 1.0543E-09 0.034295"
        rpy="0 0 0" />
      <mass
        value="0.046394" />
      <inertia
        ixx="1.1191E-05"
        ixy="7.2765E-13"
        ixz="-6.4982E-07"
        iyy="1.5732E-05"
        iyz="1.3862E-13"
        izz="1.4163E-05" />
    </inertial>
    <visual>
      <origin
        xyz="0 0 0"
        rpy="0 0 0" />
      <geometry>
        <mesh
          filename="package://robot_urdf_v9/meshes/link_04.STL" />
      </geometry>
      <material
        name="">
        <color
          rgba="0.2 0.4 0.69804 1" />
      </material>
    </visual>
    <collision>
      <origin
        xyz="0 0 0"
        rpy="0 0 0" />
      <geometry>
        <mesh
          filename="package://robot_urdf_v9/meshes/link_04.STL" />
      </geometry>
    </collision>
  </link>
  <joint
    name="joint_04"
    type="revolute">
    <origin
      xyz="0 0 0.095"
      rpy="0 -1.3812 0" />
    <parent
      link="link_03" />
    <child
      link="link_04" />
    <axis
      xyz="0 -1 0" />
    <limit
      lower="-2"
      upper="2"
      effort="1.4"
      velocity="4.5" />
  </joint>
  <link
    name="link_05">
    <inertial>
      <origin
        xyz="0.0078558 -2.6023E-08 0.035139"
        rpy="0 0 0" />
      <mass
        value="0.068112" />
      <inertia
        ixx="4.4822E-05"
        ixy="3.1185E-11"
        ixz="2.3489E-06"
        iyy="4.2894E-05"
        iyz="1.0481E-10"
        izz="2.534E-05" />
    </inertial>
    <visual>
      <origin
        xyz="0 0 0"
        rpy="0 0 0" />
      <geometry>
        <mesh
          filename="package://robot_urdf_v9/meshes/link_05.STL" />
      </geometry>
      <material
        name="">
        <color
          rgba="0.50196 0.50196 0.50196 1" />
      </material>
    </visual>
    <collision>
      <origin
        xyz="0 0 0"
        rpy="0 0 0" />
      <geometry>
        <mesh
          filename="package://robot_urdf_v9/meshes/link_05.STL" />
      </geometry>
    </collision>
  </link>
  <joint
    name="joint_05"
    type="revolute">
    <origin
      xyz="0 0 0.052"
      rpy="0 0 0.17662" />
    <parent
      link="link_04" />
    <child
      link="link_05" />
    <axis
      xyz="0 0 1" />
    <limit
      lower="-2"
      upper="2"
      effort="1.4"
      velocity="4.5" />
  </joint>
  <link
    name="eef">
    <inertial>
      <origin
        xyz="-0.0085735 -1.7192E-09 -3.3611E-09"
        rpy="0 0 0" />
      <mass
        value="0.055335" />
      <inertia
        ixx="5.8626E-06"
        ixy="9.5302E-12"
        ixz="6.0728E-12"
        iyy="3.8274E-05"
        iyz="4.4865E-11"
        izz="3.8274E-05" />
    </inertial>
    <visual>
      <origin
        xyz="0 0 0"
        rpy="0 0 0" />
      <geometry>
        <mesh
          filename="package://robot_urdf_v9/meshes/eef.STL" />
      </geometry>
      <material
        name="">
        <color
          rgba="0.79216 0.81961 0.93333 1" />
      </material>
    </visual>
    <collision>
      <origin
        xyz="0 0 0"
        rpy="0 0 0" />
      <geometry>
        <mesh
          filename="package://robot_urdf_v9/meshes/eef.STL" />
      </geometry>
    </collision>
  </link>
  <joint
    name="joint_null"
    type="fixed">
    <origin
      xyz="0 0 0.092"
      rpy="0 0 0" />
    <parent
      link="link_05" />
    <child
      link="eef" />
    <axis
      xyz="0 0 0" />
  </joint>
</robot>